<?xml version="1.0"?>

<robot name="cobot">

  <!-- База -->
  <link name="base_link"/>

  <!-- Звено 1 -->
  <link name="link_1"/>
  <joint name="joint_1" type="revolute">
    <parent link="base_link"/>
    <child link="link_1"/>
    <origin xyz="0 0 0.1" rpy="0 0 0"/>
    <axis xyz="0 0 1"/>
    <limit lower="-3.14" upper="3.14" effort="1" velocity="1"/>
  </joint>

  <!-- Звено 2 -->
  <link name="link_2"/>
  <joint name="joint_2" type="revolute">
    <parent link="link_1"/>
    <child link="link_2"/>
    <origin xyz="0 0 0.2" rpy="0 0 0"/>
    <axis xyz="0 1 0"/>
    <limit lower="-1.7" upper="1.7" effort="1" velocity="1"/>
  </joint>

  <!-- Звено 3 -->
  <link name="link_3"/>
  <joint name="joint_3" type="revolute">
    <parent link="link_2"/>
    <child link="link_3"/>
    <origin xyz="0 0 0.2" rpy="0 0 0"/>
    <axis xyz="0 1 0"/>
    <limit lower="-2.0" upper="2.0" effort="1" velocity="1"/>
  </joint>

  <ros2_control name="ServoSystem" type="system">
  <hardware>
    <plugin>cobot_hardware/servo_hardware</plugin>
    <param name="fake_sensor_commands">true</param>
  </hardware>

  <joint name="joint_1">
    <command_interface name="position"/>
    <state_interface name="position"/>
  </joint>

  <joint name="joint_2">
    <command_interface name="position"/>
    <state_interface name="position"/>
  </joint>

  <joint name="joint_3">
    <command_interface name="position"/>
    <state_interface name="position"/>
  </joint>

</ros2_control>
</robot>
